Traceback (most recent call last):
  File "/home/ssorokan/miniconda3/envs/fenicsx-env/lib/python3.10/site-packages/jupyter_cache/executors/utils.py", line 51, in single_nb_execution
    executenb(
  File "/home/ssorokan/miniconda3/envs/fenicsx-env/lib/python3.10/site-packages/nbclient/client.py", line 1204, in execute
    return NotebookClient(nb=nb, resources=resources, km=km, **kwargs).execute()
  File "/home/ssorokan/miniconda3/envs/fenicsx-env/lib/python3.10/site-packages/nbclient/util.py", line 84, in wrapped
    return just_run(coro(*args, **kwargs))
  File "/home/ssorokan/miniconda3/envs/fenicsx-env/lib/python3.10/site-packages/nbclient/util.py", line 62, in just_run
    return loop.run_until_complete(coro)
  File "/home/ssorokan/miniconda3/envs/fenicsx-env/lib/python3.10/asyncio/base_events.py", line 649, in run_until_complete
    return future.result()
  File "/home/ssorokan/miniconda3/envs/fenicsx-env/lib/python3.10/site-packages/nbclient/client.py", line 663, in async_execute
    await self.async_execute_cell(
  File "/home/ssorokan/miniconda3/envs/fenicsx-env/lib/python3.10/site-packages/nbclient/client.py", line 965, in async_execute_cell
    await self._check_raise_for_error(cell, cell_index, exec_reply)
  File "/home/ssorokan/miniconda3/envs/fenicsx-env/lib/python3.10/site-packages/nbclient/client.py", line 862, in _check_raise_for_error
    raise CellExecutionError.from_cell_and_msg(cell, exec_reply_content)
nbclient.exceptions.CellExecutionError: An error occurred while executing the following cell:
------------------
grid.point_data["u_err"]
------------------

[0;31m---------------------------------------------------------------------------[0m
[0;31mKeyError[0m                                  Traceback (most recent call last)
Cell [0;32mIn [15], line 1[0m
[0;32m----> 1[0m [43mgrid[49m[38;5;241;43m.[39;49m[43mpoint_data[49m[43m[[49m[38;5;124;43m"[39;49m[38;5;124;43mu_err[39;49m[38;5;124;43m"[39;49m[43m][49m

File [0;32m~/miniconda3/envs/fenicsx-env/lib/python3.10/site-packages/pyvista/core/datasetattributes.py:215[0m, in [0;36mDataSetAttributes.__getitem__[0;34m(self, key)[0m
[1;32m    213[0m [38;5;28;01mif[39;00m [38;5;129;01mnot[39;00m [38;5;28misinstance[39m(key, [38;5;28mstr[39m):
[1;32m    214[0m     [38;5;28;01mraise[39;00m [38;5;167;01mTypeError[39;00m([38;5;124m'[39m[38;5;124mOnly strings are valid keys for DataSetAttributes.[39m[38;5;124m'[39m)
[0;32m--> 215[0m [38;5;28;01mreturn[39;00m [38;5;28;43mself[39;49m[38;5;241;43m.[39;49m[43mget_array[49m[43m([49m[43mkey[49m[43m)[49m

File [0;32m~/miniconda3/envs/fenicsx-env/lib/python3.10/site-packages/pyvista/core/datasetattributes.py:542[0m, in [0;36mDataSetAttributes.get_array[0;34m(self, key)[0m
[1;32m    540[0m     vtk_arr [38;5;241m=[39m [38;5;28mself[39m[38;5;241m.[39mGetAbstractArray(key)
[1;32m    541[0m     [38;5;28;01mif[39;00m vtk_arr [38;5;129;01mis[39;00m [38;5;28;01mNone[39;00m:
[0;32m--> 542[0m         [38;5;28;01mraise[39;00m [38;5;167;01mKeyError[39;00m([38;5;124mf[39m[38;5;124m'[39m[38;5;132;01m{[39;00mkey[38;5;132;01m}[39;00m[38;5;124m'[39m)
[1;32m    543[0m narray [38;5;241m=[39m pyvista_ndarray(vtk_arr, dataset[38;5;241m=[39m[38;5;28mself[39m[38;5;241m.[39mdataset, association[38;5;241m=[39m[38;5;28mself[39m[38;5;241m.[39massociation)
[1;32m    544[0m [38;5;28;01mreturn[39;00m [38;5;28mself[39m[38;5;241m.[39m_patch_type(narray)

[0;31mKeyError[0m: 'u_err'
KeyError: 'u_err'

